{"ast":null,"code":"/**\n  `rethrow` will rethrow an error on the next turn of the JavaScript event\n  loop in order to aid debugging.\n\n  Promises A+ specifies that any exceptions that occur with a promise must be\n  caught by the promises implementation and bubbled to the last handler. For\n  this reason, it is recommended that you always specify a second rejection\n  handler function to `then`. However, `rethrow` will throw the exception\n  outside of the promise, so it bubbles up to your console if in the browser,\n  or domain/cause uncaught exception in Node. `rethrow` will also throw the\n  error again so the error can be handled by the promise per the spec.\n\n  ```javascript\n  import { rethrow } from 'rsvp';\n\n  function throws(){\n    throw new Error('Whoops!');\n  }\n\n  let promise = new Promise(function(resolve, reject){\n    throws();\n  });\n\n  promise.catch(rethrow).then(function(){\n    // Code here doesn't run because the promise became rejected due to an\n    // error!\n  }, function (err){\n    // handle the error here\n  });\n  ```\n\n  The 'Whoops' error will be thrown on the next turn of the event loop\n  and you can watch for it in your console. You can also handle it using a\n  rejection handler given to `.then` or `.catch` on the returned promise.\n\n  @method rethrow\n  @public\n  @static\n  @for rsvp\n  @param {Error} reason reason the promise became rejected.\n  @throws Error\n  @static\n*/\nexport default function rethrow(reason) {\n  setTimeout(() => {\n    throw reason;\n  });\n  throw reason;\n}","map":{"version":3,"sources":["/Users/nguyenquytoan/Desktop/PTUDW-17TN-Nhom05-USFL/react-usfl/PTUDW-17TN-Nhom05/node_modules/rsvp/lib/rsvp/rethrow.js"],"names":["rethrow","reason","setTimeout"],"mappings":"AAAA;;;;;;;;;;;;;;;;;;;;;;;;;;;;;;;;;;;;;;;;;;;AA2CA,eAAe,SAASA,OAAT,CAAiBC,MAAjB,EAAyB;AACtCC,EAAAA,UAAU,CAAC,MAAM;AACf,UAAMD,MAAN;AACD,GAFS,CAAV;AAGA,QAAMA,MAAN;AACD","sourcesContent":["/**\n  `rethrow` will rethrow an error on the next turn of the JavaScript event\n  loop in order to aid debugging.\n\n  Promises A+ specifies that any exceptions that occur with a promise must be\n  caught by the promises implementation and bubbled to the last handler. For\n  this reason, it is recommended that you always specify a second rejection\n  handler function to `then`. However, `rethrow` will throw the exception\n  outside of the promise, so it bubbles up to your console if in the browser,\n  or domain/cause uncaught exception in Node. `rethrow` will also throw the\n  error again so the error can be handled by the promise per the spec.\n\n  ```javascript\n  import { rethrow } from 'rsvp';\n\n  function throws(){\n    throw new Error('Whoops!');\n  }\n\n  let promise = new Promise(function(resolve, reject){\n    throws();\n  });\n\n  promise.catch(rethrow).then(function(){\n    // Code here doesn't run because the promise became rejected due to an\n    // error!\n  }, function (err){\n    // handle the error here\n  });\n  ```\n\n  The 'Whoops' error will be thrown on the next turn of the event loop\n  and you can watch for it in your console. You can also handle it using a\n  rejection handler given to `.then` or `.catch` on the returned promise.\n\n  @method rethrow\n  @public\n  @static\n  @for rsvp\n  @param {Error} reason reason the promise became rejected.\n  @throws Error\n  @static\n*/\nexport default function rethrow(reason) {\n  setTimeout(() => {\n    throw reason;\n  });\n  throw reason;\n}\n"]},"metadata":{},"sourceType":"module"}